Traceback (most recent call last):
  File "yubihsm/backends/http.py", line 48, in transceive
  File "requests/models.py", line 1021, in raise_for_status
requests.exceptions.HTTPError: 500 Server Error: Internal Server Error for url: http://localhost:12345/connector/api

During handling of the above exception, another exception occurred:

Traceback (most recent call last):
  File "DeviceCertificateProvisioner.py", line 1240, in <module>
  File "yubihsm/core.py", line 121, in get_device_info
  File "yubihsm/core.py", line 113, in send_cmd
  File "yubihsm/core.py", line 102, in _transceive
  File "yubihsm/backends/http.py", line 51, in transceive
yubihsm.exceptions.YubiHsmConnectionError: 500 Server Error: Internal Server Error for url: http://localhost:12345/connector/api
[30] Failed to execute script 'DeviceCertificateProvisioner' due to unhandled exception!
